<?xml version="1.0" ?>
<robot name="staubli_tx200" xmlns:xacro="http://ros.org/wiki/xacro">
  <!-- RAL 1028 -->
  <!-- RAL 1018 -->
  <!-- RAL 9016 -->
  <!-- RAL 7043 -->
  <!-- links -->
  <link name="rail">
    <visual>
      <origin rpy="0 3.141592653589793 0" xyz="0 0 3.920"/>
      <geometry>
        <mesh filename="meshes/staeubli_tx200/visual/rail.dae"/>
      </geometry>
      <material name="">
        <color rgba="1.0 0.607843137255 0.0 1.0"/>
      </material>
    </visual>
  </link>
  <link name="linear_axis">
    <visual>
      <origin rpy="0 3.141592653589793 0" xyz="0 0 3.920"/>
      <geometry>
        <mesh filename="meshes/staeubli_tx200/visual/linear_axis.dae"/>
      </geometry>
      <material name="">
        <color rgba="1.0 0.607843137255 0.0 1.0"/>
      </material>
    </visual>
  </link>
  <link name="base_link">
    <visual>
      <origin rpy="0 3.141592653589793 0" xyz="0 0 3.920"/>
      <geometry>
        <mesh filename="meshes/staeubli_tx200/visual/base_link.dae"/>
      </geometry>
      <material name="">
        <color rgba="1.0 0.607843137255 0.0 1.0"/>
      </material>
    </visual>
  </link>
  <link name="link_1">
    <visual>
      <origin rpy="0 3.141592653589793 0" xyz="0 0 0"/>
      <geometry>
        <mesh filename="meshes/staeubli_tx200/visual/link_1.dae"/>
      </geometry>
      <material name="">
        <color rgba="1.0 0.607843137255 0.0 1.0"/>
      </material>
    </visual>
  </link>
  <link name="link_2">
    <visual>
      <origin rpy="0 3.141592653589793 0" xyz="0.25 0 0.642"/>
      <geometry>
        <mesh filename="meshes/staeubli_tx200/visual/link_2.dae"/>
      </geometry>
      <material name="">
        <color rgba="1.0 0.607843137255 0.0 1.0"/>
      </material>
    </visual>
  </link>
  <link name="link_3">
    <visual>
      <origin rpy="0 3.141592653589793 0" xyz="0.25 0 1.592"/>
      <geometry>
        <mesh filename="meshes/staeubli_tx200/visual/link_3.dae"/>
      </geometry>
      <material name="">
        <color rgba="1.0 0.607843137255 0.0 1.0"/>
      </material>
    </visual>
  </link>
  <link name="link_4">
    <visual>
      <origin rpy="0 3.141592653589793 0" xyz="0.25 0 1.592"/>
      <geometry>
        <mesh filename="meshes/staeubli_tx200/visual/link_4.dae"/>
      </geometry>
      <material name="">
        <color rgba="1.0 0.607843137255 0.0 1.0"/>
      </material>
    </visual>
  </link>
  <link name="link_5">
    <visual>
      <origin rpy="0 3.141592653589793 0" xyz="0.25 0 2.392"/>
      <geometry>
        <mesh filename="meshes/staeubli_tx200/visual/link_5.dae"/>
      </geometry>
      <material name="">
        <color rgba="0.529411764706 0.521568627451 0.505882352941 1.0"/>
      </material>
    </visual>
  </link>
  <link name="link_6">
    <visual>
      <origin rpy="0 3.141592653589793 0" xyz="0.25 0 2.392"/>
      <geometry>
        <mesh filename="meshes/staeubli_tx200/visual/link_6.dae"/>
      </geometry>
      <material name="">
        <color rgba="0.529411764706 0.521568627451 0.505882352941 1.0"/>
      </material>
    </visual>
  </link>
  <link name="adapter">
    <visual>
      <origin rpy="0 3.141592653589793 0" xyz="0. 0 0.24"/>
      <geometry>
        <mesh filename= "meshes/staeubli_tx200/visual/tool_adapter_plate.dae"/>
      </geometry>
      <material name="">
        <color rgba="0.829411764706 0.821568627451 0.805882352941 1.0"/>
      </material>
    </visual>
  </link>
  <link name="detector">
    <visual>
      <origin rpy="0 3.141592653589793 0" xyz="0. 0. 0.24"/>
      <geometry>
        <mesh filename= "meshes/staeubli_tx200/visual/detector_1.5M.dae"/>
      </geometry>
      <material name="">
        <color rgba="0.829411764706 0.821568627451 0.805882352941 1.0"/>
      </material>
    </visual>
  </link>
  <link name="modules">
    <visual>
      <origin rpy="0 3.141592653589793 0" xyz="0. 0. 0.24"/>
      <geometry>
        <mesh filename= "meshes/staeubli_tx200/visual/detector_1.5M_modules.dae"/>
      </geometry>
      <material name="">
        <color rgba="0.829411764706 0.821568627451 0.805882352941 1.0"/>
      </material>
    </visual>
  </link>
  <joint name="rail-linear" type="prismatic">
    <parent link="rail"/>
    <child link="linear_axis"/>
    <origin rpy="0 0. 0" xyz="-2.125 0 0."/>
    <axis xyz="1 0 0"/>
    <limit effort="692.0" lower="-0.2" upper="4." velocity="2."/>
  </joint>
  <joint name="linear_axis-base_link" type="fixed">
    <parent link="linear_axis"/>
    <child link="base_link"/>
    <origin rpy="0 0. 3.141592653589793" xyz=".0 0 0."/>
  </joint>
  <joint name="joint_1" type="revolute">
    <origin rpy="0 0 0" xyz="0 0 3.920"/>
    <parent link="base_link"/>
    <child link="link_1"/>
    <axis xyz="0 0 -1"/>
    <limit effort="692.0" lower="-2.967060" upper="2.967060" velocity="2.88"/>
    <dynamics damping="0.0" friction="0.0"/>
  </joint>
  <joint name="joint_2" type="revolute">
    <origin rpy="0 0 0" xyz="-0.25 0 -0.642"/>
    <parent link="link_1"/>
    <child link="link_2"/>
    <axis xyz="0 1 0"/>
    <limit effort="574.0" lower="-2.4" upper="2.4" velocity="2.62"/>
    <dynamics damping="0.0" friction="0.0"/>
  </joint>
  <joint name="joint_3" type="revolute">
    <origin rpy="0 0 0" xyz="0.0 0 -0.95"/>
    <parent link="link_2"/>
    <child link="link_3"/>
    <axis xyz="0 1 0"/>
    <limit effort="242.0" lower="-2.62" upper="2.62" velocity="3.32"/>
    <dynamics damping="0.0" friction="0.0"/>
  </joint>
  <joint name="joint_4" type="revolute">
    <origin rpy="0 0 0" xyz="0 0 0"/>
    <parent link="link_3"/>
    <child link="link_4"/>
    <axis xyz="0 0 -1"/>
    <limit effort="58.0" lower="-4.71" upper="4.71" velocity="5.15"/>
    <dynamics damping="0.0" friction="0.0"/>
  </joint>
  <joint name="joint_5" type="revolute">
    <origin rpy="0 0 0" xyz="0 0 -0.8"/>
    <parent link="link_4"/>
    <child link="link_5"/>
    <axis xyz="0 1 0"/>
    <limit effort="29.0" lower="-1.83" upper="2.09" velocity="4.54"/>
    <dynamics damping="0.0" friction="0.0"/>
  </joint>
  <joint name="joint_6" type="revolute">
    <origin rpy="0 0 0" xyz="0 0 0.0"/>
    <parent link="link_5"/>
    <child link="link_6"/>
    <axis xyz="0 0 -1"/>
    <limit effort="29.0" lower="-4.71" upper="4.71" velocity="7.68"/>
    <dynamics damping="0.0" friction="0.0"/>
  </joint>
  <joint name="joint_6-adapter" type="fixed">
    <parent link="link_6"/>
    <child link="adapter"/>
    <origin rpy="0 0. 0" xyz="0.25 0.0 2.15"/>
  </joint>
  <joint name="adapter-detetcor" type="fixed">
    <parent link="adapter"/>
    <child link="detector"/>
    <origin rpy="0 0. 0" xyz=".0 0 0."/>
  </joint>
  <joint name="detetcor-modules" type="fixed">
    <parent link="detector"/>
    <child link="modules"/>
    <origin rpy="0 0. 0" xyz=".0 0 0."/>
  </joint>
</robot>

